<robot
  name="victor5_description">
  <link
    name="base_link">
    <inertial>
      <origin
        xyz="-0.010878 -3.0166E-17 0.025399"
        rpy="0 0 0" />
      <mass
        value="0.054078" />
      <inertia
        ixx="2.1126E-05"
        ixy="-1.6673E-13"
        ixz="-1.6909E-07"
        iyy="5.2778E-05"
        iyz="-1.7718E-20"
        izz="4.9263E-05" />
    </inertial>
    <visual>
      <origin
        xyz="0 0 0"
        rpy="0 0 0" />
      <geometry>
        <mesh
          filename="package://victor5_description/meshes/base_link.STL" />
      </geometry>
      <material
        name="">
        <color
          rgba="0.77647 0.75686 0.73725 1" />
      </material>
    </visual>
    <collision>
      <origin
        xyz="0 0 0"
        rpy="0 0 0" />
      <geometry>
        <mesh
          filename="package://victor5_description/meshes/base_link.STL" />
      </geometry>
    </collision>
  </link>
  <link
    name="link1">
    <inertial>
      <origin
        xyz="-0.005859 -0.00029764 0.014273"
        rpy="0 0 0" />
      <mass
        value="0.055714" />
      <inertia
        ixx="1.2781E-05"
        ixy="6.801E-08"
        ixz="3.7239E-07"
        iyy="1.2161E-05"
        iyz="4.5227E-08"
        izz="1.8316E-05" />
    </inertial>
    <visual>
      <origin
        xyz="0 0 0"
        rpy="0 0 0" />
      <geometry>
        <mesh
          filename="package://victor5_description/meshes/link1.STL" />
      </geometry>
      <material
        name="">
        <color
          rgba="0.89804 0.91765 0.92941 1" />
      </material>
    </visual>
    <collision>
      <origin
        xyz="0 0 0"
        rpy="0 0 0" />
      <geometry>
        <mesh
          filename="package://victor5_description/meshes/link1.STL" />
      </geometry>
    </collision>
  </link>
  <joint
    name="joint1"
    type="revolute">
    <origin
      xyz="0 0 0.054"
      rpy="0 0 0" />
    <parent
      link="base_link" />
    <child
      link="link1" />
    <axis
      xyz="0 0 1" />
    <limit
      lower="-1.57"
      upper="1.57"
      effort="0"
      velocity="0" />
  </joint>
  <link
    name="link2">
    <inertial>
      <origin
        xyz="-2.3057E-07 -0.052 -0.0235"
        rpy="0 0 0" />
      <mass
        value="0.048335" />
      <inertia
        ixx="7.6992E-05"
        ixy="-2.0484E-10"
        ixz="-2.2166E-11"
        iyy="3.0796E-05"
        iyz="-4.9991E-06"
        izz="5.1135E-05" />
    </inertial>
    <visual>
      <origin
        xyz="0 0 0"
        rpy="0 0 0" />
      <geometry>
        <mesh
          filename="package://victor5_description/meshes/link2.STL" />
      </geometry>
      <material
        name="">
        <color
          rgba="0.89804 0.91765 0.92941 1" />
      </material>
    </visual>
    <collision>
      <origin
        xyz="0 0 0"
        rpy="0 0 0" />
      <geometry>
        <mesh
          filename="package://victor5_description/meshes/link2.STL" />
      </geometry>
    </collision>
  </link>
  <joint
    name="joint2"
    type="revolute">
    <origin
      xyz="-0.0325 -0.011 0.017"
      rpy="-1.5708 -2.9681E-34 1.5708" />
    <parent
      link="link1" />
    <child
      link="link2" />
    <axis
      xyz="0 0 -1" />
    <limit
      lower="-1.57"
      upper="1.57"
      effort="0"
      velocity="0" />
  </joint>
  <link
    name="link3">
    <inertial>
      <origin
        xyz="0.0030387 0.037886 -0.023412"
        rpy="0 0 0" />
      <mass
        value="0.11454" />
      <inertia
        ixx="0.00012216"
        ixy="-1.5975E-07"
        ixz="2.5822E-07"
        iyy="2.6684E-05"
        iyz="-4.2408E-06"
        izz="0.00010966" />
    </inertial>
    <visual>
      <origin
        xyz="0 0 0"
        rpy="0 0 0" />
      <geometry>
        <mesh
          filename="package://victor5_description/meshes/link3.STL" />
      </geometry>
      <material
        name="">
        <color
          rgba="0.89804 0.91765 0.92941 1" />
      </material>
    </visual>
    <collision>
      <origin
        xyz="0 0 0"
        rpy="0 0 0" />
      <geometry>
        <mesh
          filename="package://victor5_description/meshes/link3.STL" />
      </geometry>
    </collision>
  </link>
  <joint
    name="joint3"
    type="revolute">
    <origin
      xyz="0 -0.104 -0.047"
      rpy="3.1416 1.8729E-17 0" />
    <parent
      link="link2" />
    <child
      link="link3" />
    <axis
      xyz="0 0 1" />
    <limit
      lower="-1.57"
      upper="1.57"
      effort="0"
      velocity="0" />
  </joint>
  <link
    name="gripper_link">
    <inertial>
      <origin
        xyz="3.4694E-18 0 0.0010453"
        rpy="0 0 0" />
      <mass
        value="0.0019584" />
      <inertia
        ixx="5.1161E-08"
        ixy="-2.8671E-25"
        ixz="-4.2409E-24"
        iyy="5.1161E-08"
        iyz="5.1191E-24"
        izz="9.8556E-08" />
    </inertial>
    <visual>
      <origin
        xyz="0 0 0"
        rpy="0 0 0" />
      <geometry>
        <mesh
          filename="package://victor5_description/meshes/gripper_link.STL" />
      </geometry>
      <material
        name="">
        <color
          rgba="0.89804 0.91765 0.92941 1" />
      </material>
    </visual>
    <collision>
      <origin
        xyz="0 0 0"
        rpy="0 0 0" />
      <geometry>
        <mesh
          filename="package://victor5_description/meshes/gripper_link.STL" />
      </geometry>
    </collision>
  </link>
  <joint
    name="joint_gripper"
    type="revolute">
    <origin
      xyz="0 0.092 -0.011"
      rpy="1.5708 -1.5708 0" />
    <parent
      link="link3" />
    <child
      link="gripper_link" />
    <axis
      xyz="0 0 1" />
    <limit
      lower="-1.57"
      upper="1.57"
      effort="0"
      velocity="0" />
  </joint>
</robot>