<robot
  name="neo5">
  <link name="link0">
    <visual>
      <origin xyz="0 0 0" rpy="0 0 0" />
      <geometry>
        <mesh filename="package://neo5_description/meshes/link0.STL" />
      </geometry>
      <material name="">
        <color rgba="0.9 0.9 0.9 1" />
      </material>
    </visual>
    <collision>
      <origin xyz="0 0 0" rpy="0 0 0" />
      <geometry>
        <mesh filename="package://neo5_description/meshes/link0.STL" />
      </geometry>
    </collision>
  </link>
  <link name="link1">
    <visual>
      <origin xyz="0 0 0" rpy="0 0 0" />
      <geometry>
        <mesh filename="package://neo5_description/meshes/link1.STL" />
      </geometry>
      <material name="">
        <color rgba="0.9 0.9 0.9 1" />
      </material>
    </visual>
    <collision>
      <origin xyz="0 0 0" rpy="0 0 0" />
      <geometry>
        <mesh filename="package://neo5_description/meshes/link1.STL" />
      </geometry>
    </collision>
  </link>
  <joint name="joint1" type="revolute">
    <origin xyz="0 -0.001 0.041" rpy="0 0 -0.071489" />
    <parent link="link0" />
    <child  link="link1" />
    <axis xyz="0 0 1" />
    <limit effort="0" velocity="0" lower="-1.57" upper="1.57" />
  </joint>
  <link name="link2">
    <visual>
      <origin xyz="0 0 0" rpy="0 0 0" />
      <geometry>
        <mesh filename="package://neo5_description/meshes/link2.STL" />
      </geometry>
      <material name="">
        <color rgba="0.9 0.9 0.9 1" />
      </material>
    </visual>
    <collision>
      <origin xyz="0 0 0" rpy="0 0 0" />
      <geometry>
        <mesh filename="package://neo5_description/meshes/link2.STL" />
      </geometry>
    </collision>
  </link>
  <joint name="joint2" type="revolute">
    <origin xyz="0 0.0008 0.033" rpy="0 0 0.071489" />
    <parent link="link1" />
    <child  link="link2" />
    <axis xyz="1 0 0" />
    <limit effort="0" velocity="0" lower="-1.57" upper="1.57" />
  </joint>
  <link name="link3">
    <visual>
      <origin xyz="0 0 0" rpy="0 0 0" />
      <geometry>
        <mesh filename="package://neo5_description/meshes/link3.STL" />
      </geometry>
      <material name="">
        <color rgba="0.9 0.9 0.9 1" />
      </material>
    </visual>
    <collision>
      <origin xyz="0 0 0" rpy="0 0 0" />
      <geometry>
        <mesh filename="package://neo5_description/meshes/link3.STL" />
      </geometry>
    </collision>
  </link>
  <joint name="joint3" type="revolute">
    <origin xyz="0 0 0.104" rpy="0 0 0" />
    <parent link="link2" />
    <child  link="link3" />
    <axis xyz="1 0 0" />
    <limit effort="0" velocity="0" lower="-1.57" upper="1.57" />
  </joint>
  <link name="link4">
    <visual>
      <origin xyz="0 0 0" rpy="0 0 0" />
      <geometry>
        <mesh filename="package://neo5_description/meshes/link4.STL" />
      </geometry>
      <material name="">
        <color rgba="0.9 0.9 0.9 1" />
      </material>
    </visual>
    <collision>
      <origin xyz="0 0 0" rpy="0 0 0" />
      <geometry>
        <mesh filename="package://neo5_description/meshes/link4.STL" />
      </geometry>
    </collision>
  </link>
  <joint name="joint4" type="revolute">
    <origin xyz="0.011 0.0015 0.0815" rpy="0 0 0" />
    <parent link="link3" />
    <child  link="link4" />
    <axis xyz="0 0 1" />
    <limit effort="0" velocity="0" lower="-1.57" upper="1.57" />
  </joint>
  <link name="link5"/>
  <joint name="joint5" type="fixed">
    <origin xyz="0 0 0.1" rpy="0 0 0" />
    <parent link="link4" />
    <child  link="link5" />
    <axis xyz="0 0 0" />
  </joint>
</robot>